{"errorMessage": "An error occurred (ValidationException) when calling the PutItem operation: One or more parameter values were invalid: Missing the key item_id in the item", "errorType": "ClientError", "requestId": "1eb08538-da68-4f2b-96d3-95be682be52d", "stackTrace": ["  File \"/var/task/init_data.py\", line 35, in handler\n    table.put_item(Item=book)\n", "  File \"/var/lang/lib/python3.12/site-packages/boto3/resources/factory.py\", line 581, in do_action\n    response = action(self, *args, **kwargs)\n", "  File \"/var/lang/lib/python3.12/site-packages/boto3/resources/action.py\", line 88, in __call__\n    response = getattr(parent.meta.client, operation_name)(*args, **params)\n", "  File \"/var/lang/lib/python3.12/site-packages/botocore/client.py\", line 598, in _api_call\n    return self._make_api_call(operation_name, kwargs)\n", "  File \"/var/lang/lib/python3.12/site-packages/botocore/context.py\", line 123, in wrapper\n    return func(*args, **kwargs)\n", "  File \"/var/lang/lib/python3.12/site-packages/botocore/client.py\", line 1061, in _make_api_call\n    raise error_class(parsed_response, operation_name)\n"]}